07/27/2024 04:25:43 PM Logging starts
Traceback (most recent call last):
  File "./popular_projects_snippets_dataset/flask/bodies/body_275_refine_6_3.py", line 10, in <module>
    raise err from None
__main__.CustomError: A custom error occurred
Command exited with non-zero status 1
1.51user 4.06system 0:00.78elapsed 708%CPU (0avgtext+0avgdata 104672maxresident)k
0inputs+16outputs (0major+23603minor)pagefaults 0swaps
